{
 "cells": [
  {
   "cell_type": "code",
   "execution_count": 1,
   "metadata": {},
   "outputs": [
    {
     "name": "stdout",
     "output_type": "stream",
     "text": [
      "WARNING:tensorflow:\n",
      "The TensorFlow contrib module will not be included in TensorFlow 2.0.\n",
      "For more information, please see:\n",
      "  * https://github.com/tensorflow/community/blob/master/rfcs/20180907-contrib-sunset.md\n",
      "  * https://github.com/tensorflow/addons\n",
      "  * https://github.com/tensorflow/io (for I/O related ops)\n",
      "If you depend on functionality not listed there, please file an issue.\n",
      "\n"
     ]
    }
   ],
   "source": [
    "#%tensorflow_version 1.x\n",
    "import warnings\n",
    "warnings.filterwarnings('ignore')\n",
    "import os\n",
    "import math\n",
    "import random\n",
    "\n",
    "import numpy as np\n",
    "import tensorflow as tf\n",
    "import cv2\n",
    "#import tf_slim as slim\n",
    "slim = tf.contrib.slim\n",
    "#tf.__version__"
   ]
  },
  {
   "cell_type": "code",
   "execution_count": 2,
   "metadata": {},
   "outputs": [
    {
     "name": "stdout",
     "output_type": "stream",
     "text": [
      "3.7.10\n"
     ]
    }
   ],
   "source": [
    "from platform import python_version\n",
    "\n",
    "print(python_version())"
   ]
  },
  {
   "cell_type": "code",
   "execution_count": 3,
   "metadata": {},
   "outputs": [],
   "source": [
    "%matplotlib inline\n",
    "import matplotlib.pyplot as plt\n",
    "import matplotlib.image as mpimg"
   ]
  },
  {
   "cell_type": "code",
   "execution_count": 5,
   "metadata": {},
   "outputs": [],
   "source": [
    "import sys\n",
    "sys.path.append('../')"
   ]
  },
  {
   "cell_type": "code",
   "execution_count": 6,
   "metadata": {},
   "outputs": [],
   "source": [
    "#%tensorflow_version 1.x\n",
    "from nets import ssd_vgg_300, ssd_common, np_methods\n",
    "from preprocessing import ssd_vgg_preprocessing\n",
    "from notebooks import visualization"
   ]
  },
  {
   "cell_type": "code",
   "execution_count": 7,
   "metadata": {},
   "outputs": [],
   "source": [
    "#%tensorflow_version 1.x\n",
    "# TensorFlow session: grow memory when needed. TF, DO NOT USE ALL MY GPU MEMORY!!!\n",
    "gpu_options = tf.GPUOptions(allow_growth=True)\n",
    "config = tf.ConfigProto(log_device_placement=False, gpu_options=gpu_options)\n",
    "isess = tf.InteractiveSession(config=config)"
   ]
  },
  {
   "cell_type": "markdown",
   "metadata": {},
   "source": [
    "## SSD 300 Model\n",
    "\n",
    "The SSD 300 network takes 300x300 image inputs. In order to feed any image, the latter is resize to this input shape (i.e.`Resize.WARP_RESIZE`). Note that even though it may change the ratio width / height, the SSD model performs well on resized images (and it is the default behaviour in the original Caffe implementation).\n",
    "\n",
    "SSD anchors correspond to the default bounding boxes encoded in the network. The SSD net output provides offset on the coordinates and dimensions of these anchors."
   ]
  },
  {
   "cell_type": "code",
   "execution_count": 8,
   "metadata": {
    "scrolled": false
   },
   "outputs": [
    {
     "name": "stdout",
     "output_type": "stream",
     "text": [
      "WARNING:tensorflow:From ../preprocessing/ssd_vgg_preprocessing.py:318: to_float (from tensorflow.python.ops.math_ops) is deprecated and will be removed in a future version.\n",
      "Instructions for updating:\n",
      "Use `tf.cast` instead.\n",
      "WARNING:tensorflow:From ../preprocessing/tf_image.py:275: The name tf.image.resize_images is deprecated. Please use tf.image.resize instead.\n",
      "\n",
      "WARNING:tensorflow:From ../nets/ssd_vgg_300.py:450: The name tf.variable_scope is deprecated. Please use tf.compat.v1.variable_scope instead.\n",
      "\n",
      "WARNING:tensorflow:Entity <bound method Conv.call of <tensorflow.python.layers.convolutional.Conv2D object at 0x7fd8deea03d0>> could not be transformed and will be executed as-is. Please report this to the AutgoGraph team. When filing the bug, set the verbosity to 10 (on Linux, `export AUTOGRAPH_VERBOSITY=10`) and attach the full output. Cause: converting <bound method Conv.call of <tensorflow.python.layers.convolutional.Conv2D object at 0x7fd8deea03d0>>: AssertionError: Bad argument number for Name: 3, expecting 4\n",
      "WARNING: Entity <bound method Conv.call of <tensorflow.python.layers.convolutional.Conv2D object at 0x7fd8deea03d0>> could not be transformed and will be executed as-is. Please report this to the AutgoGraph team. When filing the bug, set the verbosity to 10 (on Linux, `export AUTOGRAPH_VERBOSITY=10`) and attach the full output. Cause: converting <bound method Conv.call of <tensorflow.python.layers.convolutional.Conv2D object at 0x7fd8deea03d0>>: AssertionError: Bad argument number for Name: 3, expecting 4\n",
      "WARNING:tensorflow:Entity <bound method Conv.call of <tensorflow.python.layers.convolutional.Conv2D object at 0x7fd8de76fe50>> could not be transformed and will be executed as-is. Please report this to the AutgoGraph team. When filing the bug, set the verbosity to 10 (on Linux, `export AUTOGRAPH_VERBOSITY=10`) and attach the full output. Cause: converting <bound method Conv.call of <tensorflow.python.layers.convolutional.Conv2D object at 0x7fd8de76fe50>>: AssertionError: Bad argument number for Name: 3, expecting 4\n",
      "WARNING: Entity <bound method Conv.call of <tensorflow.python.layers.convolutional.Conv2D object at 0x7fd8de76fe50>> could not be transformed and will be executed as-is. Please report this to the AutgoGraph team. When filing the bug, set the verbosity to 10 (on Linux, `export AUTOGRAPH_VERBOSITY=10`) and attach the full output. Cause: converting <bound method Conv.call of <tensorflow.python.layers.convolutional.Conv2D object at 0x7fd8de76fe50>>: AssertionError: Bad argument number for Name: 3, expecting 4\n",
      "WARNING:tensorflow:Entity <bound method Pooling2D.call of <tensorflow.python.layers.pooling.MaxPooling2D object at 0x7fd8df592b90>> could not be transformed and will be executed as-is. Please report this to the AutgoGraph team. When filing the bug, set the verbosity to 10 (on Linux, `export AUTOGRAPH_VERBOSITY=10`) and attach the full output. Cause: converting <bound method Pooling2D.call of <tensorflow.python.layers.pooling.MaxPooling2D object at 0x7fd8df592b90>>: AssertionError: Bad argument number for Name: 3, expecting 4\n",
      "WARNING: Entity <bound method Pooling2D.call of <tensorflow.python.layers.pooling.MaxPooling2D object at 0x7fd8df592b90>> could not be transformed and will be executed as-is. Please report this to the AutgoGraph team. When filing the bug, set the verbosity to 10 (on Linux, `export AUTOGRAPH_VERBOSITY=10`) and attach the full output. Cause: converting <bound method Pooling2D.call of <tensorflow.python.layers.pooling.MaxPooling2D object at 0x7fd8df592b90>>: AssertionError: Bad argument number for Name: 3, expecting 4\n",
      "WARNING:tensorflow:Entity <bound method Conv.call of <tensorflow.python.layers.convolutional.Conv2D object at 0x7fd8de76f810>> could not be transformed and will be executed as-is. Please report this to the AutgoGraph team. When filing the bug, set the verbosity to 10 (on Linux, `export AUTOGRAPH_VERBOSITY=10`) and attach the full output. Cause: converting <bound method Conv.call of <tensorflow.python.layers.convolutional.Conv2D object at 0x7fd8de76f810>>: AssertionError: Bad argument number for Name: 3, expecting 4\n",
      "WARNING: Entity <bound method Conv.call of <tensorflow.python.layers.convolutional.Conv2D object at 0x7fd8de76f810>> could not be transformed and will be executed as-is. Please report this to the AutgoGraph team. When filing the bug, set the verbosity to 10 (on Linux, `export AUTOGRAPH_VERBOSITY=10`) and attach the full output. Cause: converting <bound method Conv.call of <tensorflow.python.layers.convolutional.Conv2D object at 0x7fd8de76f810>>: AssertionError: Bad argument number for Name: 3, expecting 4\n",
      "WARNING:tensorflow:Entity <bound method Conv.call of <tensorflow.python.layers.convolutional.Conv2D object at 0x7fd8deea0310>> could not be transformed and will be executed as-is. Please report this to the AutgoGraph team. When filing the bug, set the verbosity to 10 (on Linux, `export AUTOGRAPH_VERBOSITY=10`) and attach the full output. Cause: converting <bound method Conv.call of <tensorflow.python.layers.convolutional.Conv2D object at 0x7fd8deea0310>>: AssertionError: Bad argument number for Name: 3, expecting 4\n",
      "WARNING: Entity <bound method Conv.call of <tensorflow.python.layers.convolutional.Conv2D object at 0x7fd8deea0310>> could not be transformed and will be executed as-is. Please report this to the AutgoGraph team. When filing the bug, set the verbosity to 10 (on Linux, `export AUTOGRAPH_VERBOSITY=10`) and attach the full output. Cause: converting <bound method Conv.call of <tensorflow.python.layers.convolutional.Conv2D object at 0x7fd8deea0310>>: AssertionError: Bad argument number for Name: 3, expecting 4\n",
      "WARNING:tensorflow:Entity <bound method Pooling2D.call of <tensorflow.python.layers.pooling.MaxPooling2D object at 0x7fd8df592a90>> could not be transformed and will be executed as-is. Please report this to the AutgoGraph team. When filing the bug, set the verbosity to 10 (on Linux, `export AUTOGRAPH_VERBOSITY=10`) and attach the full output. Cause: converting <bound method Pooling2D.call of <tensorflow.python.layers.pooling.MaxPooling2D object at 0x7fd8df592a90>>: AssertionError: Bad argument number for Name: 3, expecting 4\n",
      "WARNING: Entity <bound method Pooling2D.call of <tensorflow.python.layers.pooling.MaxPooling2D object at 0x7fd8df592a90>> could not be transformed and will be executed as-is. Please report this to the AutgoGraph team. When filing the bug, set the verbosity to 10 (on Linux, `export AUTOGRAPH_VERBOSITY=10`) and attach the full output. Cause: converting <bound method Pooling2D.call of <tensorflow.python.layers.pooling.MaxPooling2D object at 0x7fd8df592a90>>: AssertionError: Bad argument number for Name: 3, expecting 4\n",
      "WARNING:tensorflow:Entity <bound method Conv.call of <tensorflow.python.layers.convolutional.Conv2D object at 0x7fd8df66a3d0>> could not be transformed and will be executed as-is. Please report this to the AutgoGraph team. When filing the bug, set the verbosity to 10 (on Linux, `export AUTOGRAPH_VERBOSITY=10`) and attach the full output. Cause: converting <bound method Conv.call of <tensorflow.python.layers.convolutional.Conv2D object at 0x7fd8df66a3d0>>: AssertionError: Bad argument number for Name: 3, expecting 4\n",
      "WARNING: Entity <bound method Conv.call of <tensorflow.python.layers.convolutional.Conv2D object at 0x7fd8df66a3d0>> could not be transformed and will be executed as-is. Please report this to the AutgoGraph team. When filing the bug, set the verbosity to 10 (on Linux, `export AUTOGRAPH_VERBOSITY=10`) and attach the full output. Cause: converting <bound method Conv.call of <tensorflow.python.layers.convolutional.Conv2D object at 0x7fd8df66a3d0>>: AssertionError: Bad argument number for Name: 3, expecting 4\n",
      "WARNING:tensorflow:Entity <bound method Conv.call of <tensorflow.python.layers.convolutional.Conv2D object at 0x7fd8df64a550>> could not be transformed and will be executed as-is. Please report this to the AutgoGraph team. When filing the bug, set the verbosity to 10 (on Linux, `export AUTOGRAPH_VERBOSITY=10`) and attach the full output. Cause: converting <bound method Conv.call of <tensorflow.python.layers.convolutional.Conv2D object at 0x7fd8df64a550>>: AssertionError: Bad argument number for Name: 3, expecting 4\n"
     ]
    },
    {
     "name": "stdout",
     "output_type": "stream",
     "text": [
      "WARNING: Entity <bound method Conv.call of <tensorflow.python.layers.convolutional.Conv2D object at 0x7fd8df64a550>> could not be transformed and will be executed as-is. Please report this to the AutgoGraph team. When filing the bug, set the verbosity to 10 (on Linux, `export AUTOGRAPH_VERBOSITY=10`) and attach the full output. Cause: converting <bound method Conv.call of <tensorflow.python.layers.convolutional.Conv2D object at 0x7fd8df64a550>>: AssertionError: Bad argument number for Name: 3, expecting 4\n",
      "WARNING:tensorflow:Entity <bound method Conv.call of <tensorflow.python.layers.convolutional.Conv2D object at 0x7fd8df233090>> could not be transformed and will be executed as-is. Please report this to the AutgoGraph team. When filing the bug, set the verbosity to 10 (on Linux, `export AUTOGRAPH_VERBOSITY=10`) and attach the full output. Cause: converting <bound method Conv.call of <tensorflow.python.layers.convolutional.Conv2D object at 0x7fd8df233090>>: AssertionError: Bad argument number for Name: 3, expecting 4\n",
      "WARNING: Entity <bound method Conv.call of <tensorflow.python.layers.convolutional.Conv2D object at 0x7fd8df233090>> could not be transformed and will be executed as-is. Please report this to the AutgoGraph team. When filing the bug, set the verbosity to 10 (on Linux, `export AUTOGRAPH_VERBOSITY=10`) and attach the full output. Cause: converting <bound method Conv.call of <tensorflow.python.layers.convolutional.Conv2D object at 0x7fd8df233090>>: AssertionError: Bad argument number for Name: 3, expecting 4\n",
      "WARNING:tensorflow:Entity <bound method Pooling2D.call of <tensorflow.python.layers.pooling.MaxPooling2D object at 0x7fd8df592ad0>> could not be transformed and will be executed as-is. Please report this to the AutgoGraph team. When filing the bug, set the verbosity to 10 (on Linux, `export AUTOGRAPH_VERBOSITY=10`) and attach the full output. Cause: converting <bound method Pooling2D.call of <tensorflow.python.layers.pooling.MaxPooling2D object at 0x7fd8df592ad0>>: AssertionError: Bad argument number for Name: 3, expecting 4\n",
      "WARNING: Entity <bound method Pooling2D.call of <tensorflow.python.layers.pooling.MaxPooling2D object at 0x7fd8df592ad0>> could not be transformed and will be executed as-is. Please report this to the AutgoGraph team. When filing the bug, set the verbosity to 10 (on Linux, `export AUTOGRAPH_VERBOSITY=10`) and attach the full output. Cause: converting <bound method Pooling2D.call of <tensorflow.python.layers.pooling.MaxPooling2D object at 0x7fd8df592ad0>>: AssertionError: Bad argument number for Name: 3, expecting 4\n",
      "WARNING:tensorflow:Entity <bound method Conv.call of <tensorflow.python.layers.convolutional.Conv2D object at 0x7fd8df66a8d0>> could not be transformed and will be executed as-is. Please report this to the AutgoGraph team. When filing the bug, set the verbosity to 10 (on Linux, `export AUTOGRAPH_VERBOSITY=10`) and attach the full output. Cause: converting <bound method Conv.call of <tensorflow.python.layers.convolutional.Conv2D object at 0x7fd8df66a8d0>>: AssertionError: Bad argument number for Name: 3, expecting 4\n",
      "WARNING: Entity <bound method Conv.call of <tensorflow.python.layers.convolutional.Conv2D object at 0x7fd8df66a8d0>> could not be transformed and will be executed as-is. Please report this to the AutgoGraph team. When filing the bug, set the verbosity to 10 (on Linux, `export AUTOGRAPH_VERBOSITY=10`) and attach the full output. Cause: converting <bound method Conv.call of <tensorflow.python.layers.convolutional.Conv2D object at 0x7fd8df66a8d0>>: AssertionError: Bad argument number for Name: 3, expecting 4\n",
      "WARNING:tensorflow:Entity <bound method Conv.call of <tensorflow.python.layers.convolutional.Conv2D object at 0x7fd8de76f090>> could not be transformed and will be executed as-is. Please report this to the AutgoGraph team. When filing the bug, set the verbosity to 10 (on Linux, `export AUTOGRAPH_VERBOSITY=10`) and attach the full output. Cause: converting <bound method Conv.call of <tensorflow.python.layers.convolutional.Conv2D object at 0x7fd8de76f090>>: AssertionError: Bad argument number for Name: 3, expecting 4\n",
      "WARNING: Entity <bound method Conv.call of <tensorflow.python.layers.convolutional.Conv2D object at 0x7fd8de76f090>> could not be transformed and will be executed as-is. Please report this to the AutgoGraph team. When filing the bug, set the verbosity to 10 (on Linux, `export AUTOGRAPH_VERBOSITY=10`) and attach the full output. Cause: converting <bound method Conv.call of <tensorflow.python.layers.convolutional.Conv2D object at 0x7fd8de76f090>>: AssertionError: Bad argument number for Name: 3, expecting 4\n",
      "WARNING:tensorflow:Entity <bound method Conv.call of <tensorflow.python.layers.convolutional.Conv2D object at 0x7fd8df66a3d0>> could not be transformed and will be executed as-is. Please report this to the AutgoGraph team. When filing the bug, set the verbosity to 10 (on Linux, `export AUTOGRAPH_VERBOSITY=10`) and attach the full output. Cause: converting <bound method Conv.call of <tensorflow.python.layers.convolutional.Conv2D object at 0x7fd8df66a3d0>>: AssertionError: Bad argument number for Name: 3, expecting 4\n",
      "WARNING: Entity <bound method Conv.call of <tensorflow.python.layers.convolutional.Conv2D object at 0x7fd8df66a3d0>> could not be transformed and will be executed as-is. Please report this to the AutgoGraph team. When filing the bug, set the verbosity to 10 (on Linux, `export AUTOGRAPH_VERBOSITY=10`) and attach the full output. Cause: converting <bound method Conv.call of <tensorflow.python.layers.convolutional.Conv2D object at 0x7fd8df66a3d0>>: AssertionError: Bad argument number for Name: 3, expecting 4\n",
      "WARNING:tensorflow:Entity <bound method Pooling2D.call of <tensorflow.python.layers.pooling.MaxPooling2D object at 0x7fd8df77cd50>> could not be transformed and will be executed as-is. Please report this to the AutgoGraph team. When filing the bug, set the verbosity to 10 (on Linux, `export AUTOGRAPH_VERBOSITY=10`) and attach the full output. Cause: converting <bound method Pooling2D.call of <tensorflow.python.layers.pooling.MaxPooling2D object at 0x7fd8df77cd50>>: AssertionError: Bad argument number for Name: 3, expecting 4\n",
      "WARNING: Entity <bound method Pooling2D.call of <tensorflow.python.layers.pooling.MaxPooling2D object at 0x7fd8df77cd50>> could not be transformed and will be executed as-is. Please report this to the AutgoGraph team. When filing the bug, set the verbosity to 10 (on Linux, `export AUTOGRAPH_VERBOSITY=10`) and attach the full output. Cause: converting <bound method Pooling2D.call of <tensorflow.python.layers.pooling.MaxPooling2D object at 0x7fd8df77cd50>>: AssertionError: Bad argument number for Name: 3, expecting 4\n",
      "WARNING:tensorflow:Entity <bound method Conv.call of <tensorflow.python.layers.convolutional.Conv2D object at 0x7fd8df632f90>> could not be transformed and will be executed as-is. Please report this to the AutgoGraph team. When filing the bug, set the verbosity to 10 (on Linux, `export AUTOGRAPH_VERBOSITY=10`) and attach the full output. Cause: converting <bound method Conv.call of <tensorflow.python.layers.convolutional.Conv2D object at 0x7fd8df632f90>>: AssertionError: Bad argument number for Name: 3, expecting 4\n",
      "WARNING: Entity <bound method Conv.call of <tensorflow.python.layers.convolutional.Conv2D object at 0x7fd8df632f90>> could not be transformed and will be executed as-is. Please report this to the AutgoGraph team. When filing the bug, set the verbosity to 10 (on Linux, `export AUTOGRAPH_VERBOSITY=10`) and attach the full output. Cause: converting <bound method Conv.call of <tensorflow.python.layers.convolutional.Conv2D object at 0x7fd8df632f90>>: AssertionError: Bad argument number for Name: 3, expecting 4\n",
      "WARNING:tensorflow:Entity <bound method Conv.call of <tensorflow.python.layers.convolutional.Conv2D object at 0x7fd8df67d350>> could not be transformed and will be executed as-is. Please report this to the AutgoGraph team. When filing the bug, set the verbosity to 10 (on Linux, `export AUTOGRAPH_VERBOSITY=10`) and attach the full output. Cause: converting <bound method Conv.call of <tensorflow.python.layers.convolutional.Conv2D object at 0x7fd8df67d350>>: AssertionError: Bad argument number for Name: 3, expecting 4\n"
     ]
    },
    {
     "name": "stdout",
     "output_type": "stream",
     "text": [
      "WARNING: Entity <bound method Conv.call of <tensorflow.python.layers.convolutional.Conv2D object at 0x7fd8df67d350>> could not be transformed and will be executed as-is. Please report this to the AutgoGraph team. When filing the bug, set the verbosity to 10 (on Linux, `export AUTOGRAPH_VERBOSITY=10`) and attach the full output. Cause: converting <bound method Conv.call of <tensorflow.python.layers.convolutional.Conv2D object at 0x7fd8df67d350>>: AssertionError: Bad argument number for Name: 3, expecting 4\n",
      "WARNING:tensorflow:Entity <bound method Conv.call of <tensorflow.python.layers.convolutional.Conv2D object at 0x7fd8df632f90>> could not be transformed and will be executed as-is. Please report this to the AutgoGraph team. When filing the bug, set the verbosity to 10 (on Linux, `export AUTOGRAPH_VERBOSITY=10`) and attach the full output. Cause: converting <bound method Conv.call of <tensorflow.python.layers.convolutional.Conv2D object at 0x7fd8df632f90>>: AssertionError: Bad argument number for Name: 3, expecting 4\n",
      "WARNING: Entity <bound method Conv.call of <tensorflow.python.layers.convolutional.Conv2D object at 0x7fd8df632f90>> could not be transformed and will be executed as-is. Please report this to the AutgoGraph team. When filing the bug, set the verbosity to 10 (on Linux, `export AUTOGRAPH_VERBOSITY=10`) and attach the full output. Cause: converting <bound method Conv.call of <tensorflow.python.layers.convolutional.Conv2D object at 0x7fd8df632f90>>: AssertionError: Bad argument number for Name: 3, expecting 4\n",
      "WARNING:tensorflow:Entity <bound method Pooling2D.call of <tensorflow.python.layers.pooling.MaxPooling2D object at 0x7fd8de76ef10>> could not be transformed and will be executed as-is. Please report this to the AutgoGraph team. When filing the bug, set the verbosity to 10 (on Linux, `export AUTOGRAPH_VERBOSITY=10`) and attach the full output. Cause: converting <bound method Pooling2D.call of <tensorflow.python.layers.pooling.MaxPooling2D object at 0x7fd8de76ef10>>: AssertionError: Bad argument number for Name: 3, expecting 4\n",
      "WARNING: Entity <bound method Pooling2D.call of <tensorflow.python.layers.pooling.MaxPooling2D object at 0x7fd8de76ef10>> could not be transformed and will be executed as-is. Please report this to the AutgoGraph team. When filing the bug, set the verbosity to 10 (on Linux, `export AUTOGRAPH_VERBOSITY=10`) and attach the full output. Cause: converting <bound method Pooling2D.call of <tensorflow.python.layers.pooling.MaxPooling2D object at 0x7fd8de76ef10>>: AssertionError: Bad argument number for Name: 3, expecting 4\n",
      "WARNING:tensorflow:Entity <bound method Conv.call of <tensorflow.python.layers.convolutional.Conv2D object at 0x7fd8df64a550>> could not be transformed and will be executed as-is. Please report this to the AutgoGraph team. When filing the bug, set the verbosity to 10 (on Linux, `export AUTOGRAPH_VERBOSITY=10`) and attach the full output. Cause: converting <bound method Conv.call of <tensorflow.python.layers.convolutional.Conv2D object at 0x7fd8df64a550>>: AssertionError: Bad argument number for Name: 3, expecting 4\n",
      "WARNING: Entity <bound method Conv.call of <tensorflow.python.layers.convolutional.Conv2D object at 0x7fd8df64a550>> could not be transformed and will be executed as-is. Please report this to the AutgoGraph team. When filing the bug, set the verbosity to 10 (on Linux, `export AUTOGRAPH_VERBOSITY=10`) and attach the full output. Cause: converting <bound method Conv.call of <tensorflow.python.layers.convolutional.Conv2D object at 0x7fd8df64a550>>: AssertionError: Bad argument number for Name: 3, expecting 4\n",
      "WARNING:tensorflow:From ../nets/ssd_vgg_300.py:476: dropout (from tensorflow.python.layers.core) is deprecated and will be removed in a future version.\n",
      "Instructions for updating:\n",
      "Use keras.layers.dropout instead.\n",
      "WARNING:tensorflow:Entity <bound method Dropout.call of <tensorflow.python.layers.core.Dropout object at 0x7fd8df64a550>> could not be transformed and will be executed as-is. Please report this to the AutgoGraph team. When filing the bug, set the verbosity to 10 (on Linux, `export AUTOGRAPH_VERBOSITY=10`) and attach the full output. Cause: converting <bound method Dropout.call of <tensorflow.python.layers.core.Dropout object at 0x7fd8df64a550>>: AssertionError: Bad argument number for Name: 3, expecting 4\n",
      "WARNING: Entity <bound method Dropout.call of <tensorflow.python.layers.core.Dropout object at 0x7fd8df64a550>> could not be transformed and will be executed as-is. Please report this to the AutgoGraph team. When filing the bug, set the verbosity to 10 (on Linux, `export AUTOGRAPH_VERBOSITY=10`) and attach the full output. Cause: converting <bound method Dropout.call of <tensorflow.python.layers.core.Dropout object at 0x7fd8df64a550>>: AssertionError: Bad argument number for Name: 3, expecting 4\n",
      "WARNING:tensorflow:Entity <bound method Conv.call of <tensorflow.python.layers.convolutional.Conv2D object at 0x7fd8df53b9d0>> could not be transformed and will be executed as-is. Please report this to the AutgoGraph team. When filing the bug, set the verbosity to 10 (on Linux, `export AUTOGRAPH_VERBOSITY=10`) and attach the full output. Cause: converting <bound method Conv.call of <tensorflow.python.layers.convolutional.Conv2D object at 0x7fd8df53b9d0>>: AssertionError: Bad argument number for Name: 3, expecting 4\n",
      "WARNING: Entity <bound method Conv.call of <tensorflow.python.layers.convolutional.Conv2D object at 0x7fd8df53b9d0>> could not be transformed and will be executed as-is. Please report this to the AutgoGraph team. When filing the bug, set the verbosity to 10 (on Linux, `export AUTOGRAPH_VERBOSITY=10`) and attach the full output. Cause: converting <bound method Conv.call of <tensorflow.python.layers.convolutional.Conv2D object at 0x7fd8df53b9d0>>: AssertionError: Bad argument number for Name: 3, expecting 4\n",
      "WARNING:tensorflow:Entity <bound method Dropout.call of <tensorflow.python.layers.core.Dropout object at 0x7fd8df53b9d0>> could not be transformed and will be executed as-is. Please report this to the AutgoGraph team. When filing the bug, set the verbosity to 10 (on Linux, `export AUTOGRAPH_VERBOSITY=10`) and attach the full output. Cause: converting <bound method Dropout.call of <tensorflow.python.layers.core.Dropout object at 0x7fd8df53b9d0>>: AssertionError: Bad argument number for Name: 3, expecting 4\n",
      "WARNING: Entity <bound method Dropout.call of <tensorflow.python.layers.core.Dropout object at 0x7fd8df53b9d0>> could not be transformed and will be executed as-is. Please report this to the AutgoGraph team. When filing the bug, set the verbosity to 10 (on Linux, `export AUTOGRAPH_VERBOSITY=10`) and attach the full output. Cause: converting <bound method Dropout.call of <tensorflow.python.layers.core.Dropout object at 0x7fd8df53b9d0>>: AssertionError: Bad argument number for Name: 3, expecting 4\n",
      "WARNING:tensorflow:Entity <bound method Conv.call of <tensorflow.python.layers.convolutional.Conv2D object at 0x7fd8df592ad0>> could not be transformed and will be executed as-is. Please report this to the AutgoGraph team. When filing the bug, set the verbosity to 10 (on Linux, `export AUTOGRAPH_VERBOSITY=10`) and attach the full output. Cause: converting <bound method Conv.call of <tensorflow.python.layers.convolutional.Conv2D object at 0x7fd8df592ad0>>: AssertionError: Bad argument number for Name: 3, expecting 4\n",
      "WARNING: Entity <bound method Conv.call of <tensorflow.python.layers.convolutional.Conv2D object at 0x7fd8df592ad0>> could not be transformed and will be executed as-is. Please report this to the AutgoGraph team. When filing the bug, set the verbosity to 10 (on Linux, `export AUTOGRAPH_VERBOSITY=10`) and attach the full output. Cause: converting <bound method Conv.call of <tensorflow.python.layers.convolutional.Conv2D object at 0x7fd8df592ad0>>: AssertionError: Bad argument number for Name: 3, expecting 4\n",
      "WARNING:tensorflow:Entity <bound method Conv.call of <tensorflow.python.layers.convolutional.Conv2D object at 0x7fd8e0168a10>> could not be transformed and will be executed as-is. Please report this to the AutgoGraph team. When filing the bug, set the verbosity to 10 (on Linux, `export AUTOGRAPH_VERBOSITY=10`) and attach the full output. Cause: converting <bound method Conv.call of <tensorflow.python.layers.convolutional.Conv2D object at 0x7fd8e0168a10>>: AssertionError: Bad argument number for Name: 3, expecting 4\n"
     ]
    },
    {
     "name": "stdout",
     "output_type": "stream",
     "text": [
      "WARNING: Entity <bound method Conv.call of <tensorflow.python.layers.convolutional.Conv2D object at 0x7fd8e0168a10>> could not be transformed and will be executed as-is. Please report this to the AutgoGraph team. When filing the bug, set the verbosity to 10 (on Linux, `export AUTOGRAPH_VERBOSITY=10`) and attach the full output. Cause: converting <bound method Conv.call of <tensorflow.python.layers.convolutional.Conv2D object at 0x7fd8e0168a10>>: AssertionError: Bad argument number for Name: 3, expecting 4\n",
      "WARNING:tensorflow:Entity <bound method Conv.call of <tensorflow.python.layers.convolutional.Conv2D object at 0x7fd8e0323b10>> could not be transformed and will be executed as-is. Please report this to the AutgoGraph team. When filing the bug, set the verbosity to 10 (on Linux, `export AUTOGRAPH_VERBOSITY=10`) and attach the full output. Cause: converting <bound method Conv.call of <tensorflow.python.layers.convolutional.Conv2D object at 0x7fd8e0323b10>>: AssertionError: Bad argument number for Name: 3, expecting 4\n",
      "WARNING: Entity <bound method Conv.call of <tensorflow.python.layers.convolutional.Conv2D object at 0x7fd8e0323b10>> could not be transformed and will be executed as-is. Please report this to the AutgoGraph team. When filing the bug, set the verbosity to 10 (on Linux, `export AUTOGRAPH_VERBOSITY=10`) and attach the full output. Cause: converting <bound method Conv.call of <tensorflow.python.layers.convolutional.Conv2D object at 0x7fd8e0323b10>>: AssertionError: Bad argument number for Name: 3, expecting 4\n",
      "WARNING:tensorflow:Entity <bound method Conv.call of <tensorflow.python.layers.convolutional.Conv2D object at 0x7fd8e03a0b50>> could not be transformed and will be executed as-is. Please report this to the AutgoGraph team. When filing the bug, set the verbosity to 10 (on Linux, `export AUTOGRAPH_VERBOSITY=10`) and attach the full output. Cause: converting <bound method Conv.call of <tensorflow.python.layers.convolutional.Conv2D object at 0x7fd8e03a0b50>>: AssertionError: Bad argument number for Name: 3, expecting 4\n",
      "WARNING: Entity <bound method Conv.call of <tensorflow.python.layers.convolutional.Conv2D object at 0x7fd8e03a0b50>> could not be transformed and will be executed as-is. Please report this to the AutgoGraph team. When filing the bug, set the verbosity to 10 (on Linux, `export AUTOGRAPH_VERBOSITY=10`) and attach the full output. Cause: converting <bound method Conv.call of <tensorflow.python.layers.convolutional.Conv2D object at 0x7fd8e03a0b50>>: AssertionError: Bad argument number for Name: 3, expecting 4\n",
      "WARNING:tensorflow:Entity <bound method Conv.call of <tensorflow.python.layers.convolutional.Conv2D object at 0x7fd8df66d390>> could not be transformed and will be executed as-is. Please report this to the AutgoGraph team. When filing the bug, set the verbosity to 10 (on Linux, `export AUTOGRAPH_VERBOSITY=10`) and attach the full output. Cause: converting <bound method Conv.call of <tensorflow.python.layers.convolutional.Conv2D object at 0x7fd8df66d390>>: AssertionError: Bad argument number for Name: 3, expecting 4\n",
      "WARNING: Entity <bound method Conv.call of <tensorflow.python.layers.convolutional.Conv2D object at 0x7fd8df66d390>> could not be transformed and will be executed as-is. Please report this to the AutgoGraph team. When filing the bug, set the verbosity to 10 (on Linux, `export AUTOGRAPH_VERBOSITY=10`) and attach the full output. Cause: converting <bound method Conv.call of <tensorflow.python.layers.convolutional.Conv2D object at 0x7fd8df66d390>>: AssertionError: Bad argument number for Name: 3, expecting 4\n",
      "WARNING:tensorflow:Entity <bound method Conv.call of <tensorflow.python.layers.convolutional.Conv2D object at 0x7fd8e03ef290>> could not be transformed and will be executed as-is. Please report this to the AutgoGraph team. When filing the bug, set the verbosity to 10 (on Linux, `export AUTOGRAPH_VERBOSITY=10`) and attach the full output. Cause: converting <bound method Conv.call of <tensorflow.python.layers.convolutional.Conv2D object at 0x7fd8e03ef290>>: AssertionError: Bad argument number for Name: 3, expecting 4\n",
      "WARNING: Entity <bound method Conv.call of <tensorflow.python.layers.convolutional.Conv2D object at 0x7fd8e03ef290>> could not be transformed and will be executed as-is. Please report this to the AutgoGraph team. When filing the bug, set the verbosity to 10 (on Linux, `export AUTOGRAPH_VERBOSITY=10`) and attach the full output. Cause: converting <bound method Conv.call of <tensorflow.python.layers.convolutional.Conv2D object at 0x7fd8e03ef290>>: AssertionError: Bad argument number for Name: 3, expecting 4\n",
      "WARNING:tensorflow:Entity <bound method Conv.call of <tensorflow.python.layers.convolutional.Conv2D object at 0x7fd8df66d590>> could not be transformed and will be executed as-is. Please report this to the AutgoGraph team. When filing the bug, set the verbosity to 10 (on Linux, `export AUTOGRAPH_VERBOSITY=10`) and attach the full output. Cause: converting <bound method Conv.call of <tensorflow.python.layers.convolutional.Conv2D object at 0x7fd8df66d590>>: AssertionError: Bad argument number for Name: 3, expecting 4\n",
      "WARNING: Entity <bound method Conv.call of <tensorflow.python.layers.convolutional.Conv2D object at 0x7fd8df66d590>> could not be transformed and will be executed as-is. Please report this to the AutgoGraph team. When filing the bug, set the verbosity to 10 (on Linux, `export AUTOGRAPH_VERBOSITY=10`) and attach the full output. Cause: converting <bound method Conv.call of <tensorflow.python.layers.convolutional.Conv2D object at 0x7fd8df66d590>>: AssertionError: Bad argument number for Name: 3, expecting 4\n",
      "WARNING:tensorflow:Entity <bound method Conv.call of <tensorflow.python.layers.convolutional.Conv2D object at 0x7fd8e03efd90>> could not be transformed and will be executed as-is. Please report this to the AutgoGraph team. When filing the bug, set the verbosity to 10 (on Linux, `export AUTOGRAPH_VERBOSITY=10`) and attach the full output. Cause: converting <bound method Conv.call of <tensorflow.python.layers.convolutional.Conv2D object at 0x7fd8e03efd90>>: AssertionError: Bad argument number for Name: 3, expecting 4\n",
      "WARNING: Entity <bound method Conv.call of <tensorflow.python.layers.convolutional.Conv2D object at 0x7fd8e03efd90>> could not be transformed and will be executed as-is. Please report this to the AutgoGraph team. When filing the bug, set the verbosity to 10 (on Linux, `export AUTOGRAPH_VERBOSITY=10`) and attach the full output. Cause: converting <bound method Conv.call of <tensorflow.python.layers.convolutional.Conv2D object at 0x7fd8e03efd90>>: AssertionError: Bad argument number for Name: 3, expecting 4\n",
      "WARNING:tensorflow:Entity <bound method Conv.call of <tensorflow.python.layers.convolutional.Conv2D object at 0x7fd8df67d850>> could not be transformed and will be executed as-is. Please report this to the AutgoGraph team. When filing the bug, set the verbosity to 10 (on Linux, `export AUTOGRAPH_VERBOSITY=10`) and attach the full output. Cause: converting <bound method Conv.call of <tensorflow.python.layers.convolutional.Conv2D object at 0x7fd8df67d850>>: AssertionError: Bad argument number for Name: 3, expecting 4\n",
      "WARNING: Entity <bound method Conv.call of <tensorflow.python.layers.convolutional.Conv2D object at 0x7fd8df67d850>> could not be transformed and will be executed as-is. Please report this to the AutgoGraph team. When filing the bug, set the verbosity to 10 (on Linux, `export AUTOGRAPH_VERBOSITY=10`) and attach the full output. Cause: converting <bound method Conv.call of <tensorflow.python.layers.convolutional.Conv2D object at 0x7fd8df67d850>>: AssertionError: Bad argument number for Name: 3, expecting 4\n",
      "WARNING:tensorflow:Entity <bound method Conv.call of <tensorflow.python.layers.convolutional.Conv2D object at 0x7fd8df66dc10>> could not be transformed and will be executed as-is. Please report this to the AutgoGraph team. When filing the bug, set the verbosity to 10 (on Linux, `export AUTOGRAPH_VERBOSITY=10`) and attach the full output. Cause: converting <bound method Conv.call of <tensorflow.python.layers.convolutional.Conv2D object at 0x7fd8df66dc10>>: AssertionError: Bad argument number for Name: 3, expecting 4\n"
     ]
    },
    {
     "name": "stdout",
     "output_type": "stream",
     "text": [
      "WARNING: Entity <bound method Conv.call of <tensorflow.python.layers.convolutional.Conv2D object at 0x7fd8df66dc10>> could not be transformed and will be executed as-is. Please report this to the AutgoGraph team. When filing the bug, set the verbosity to 10 (on Linux, `export AUTOGRAPH_VERBOSITY=10`) and attach the full output. Cause: converting <bound method Conv.call of <tensorflow.python.layers.convolutional.Conv2D object at 0x7fd8df66dc10>>: AssertionError: Bad argument number for Name: 3, expecting 4\n",
      "WARNING:tensorflow:Entity <bound method Conv.call of <tensorflow.python.layers.convolutional.Conv2D object at 0x7fd8df625490>> could not be transformed and will be executed as-is. Please report this to the AutgoGraph team. When filing the bug, set the verbosity to 10 (on Linux, `export AUTOGRAPH_VERBOSITY=10`) and attach the full output. Cause: converting <bound method Conv.call of <tensorflow.python.layers.convolutional.Conv2D object at 0x7fd8df625490>>: AssertionError: Bad argument number for Name: 3, expecting 4\n",
      "WARNING: Entity <bound method Conv.call of <tensorflow.python.layers.convolutional.Conv2D object at 0x7fd8df625490>> could not be transformed and will be executed as-is. Please report this to the AutgoGraph team. When filing the bug, set the verbosity to 10 (on Linux, `export AUTOGRAPH_VERBOSITY=10`) and attach the full output. Cause: converting <bound method Conv.call of <tensorflow.python.layers.convolutional.Conv2D object at 0x7fd8df625490>>: AssertionError: Bad argument number for Name: 3, expecting 4\n",
      "WARNING:tensorflow:Entity <bound method Conv.call of <tensorflow.python.layers.convolutional.Conv2D object at 0x7fd8e0751550>> could not be transformed and will be executed as-is. Please report this to the AutgoGraph team. When filing the bug, set the verbosity to 10 (on Linux, `export AUTOGRAPH_VERBOSITY=10`) and attach the full output. Cause: converting <bound method Conv.call of <tensorflow.python.layers.convolutional.Conv2D object at 0x7fd8e0751550>>: AssertionError: Bad argument number for Name: 3, expecting 4\n",
      "WARNING: Entity <bound method Conv.call of <tensorflow.python.layers.convolutional.Conv2D object at 0x7fd8e0751550>> could not be transformed and will be executed as-is. Please report this to the AutgoGraph team. When filing the bug, set the verbosity to 10 (on Linux, `export AUTOGRAPH_VERBOSITY=10`) and attach the full output. Cause: converting <bound method Conv.call of <tensorflow.python.layers.convolutional.Conv2D object at 0x7fd8e0751550>>: AssertionError: Bad argument number for Name: 3, expecting 4\n",
      "WARNING:tensorflow:Entity <bound method Conv.call of <tensorflow.python.layers.convolutional.Conv2D object at 0x7fd8df625110>> could not be transformed and will be executed as-is. Please report this to the AutgoGraph team. When filing the bug, set the verbosity to 10 (on Linux, `export AUTOGRAPH_VERBOSITY=10`) and attach the full output. Cause: converting <bound method Conv.call of <tensorflow.python.layers.convolutional.Conv2D object at 0x7fd8df625110>>: AssertionError: Bad argument number for Name: 3, expecting 4\n",
      "WARNING: Entity <bound method Conv.call of <tensorflow.python.layers.convolutional.Conv2D object at 0x7fd8df625110>> could not be transformed and will be executed as-is. Please report this to the AutgoGraph team. When filing the bug, set the verbosity to 10 (on Linux, `export AUTOGRAPH_VERBOSITY=10`) and attach the full output. Cause: converting <bound method Conv.call of <tensorflow.python.layers.convolutional.Conv2D object at 0x7fd8df625110>>: AssertionError: Bad argument number for Name: 3, expecting 4\n",
      "WARNING:tensorflow:Entity <bound method Conv.call of <tensorflow.python.layers.convolutional.Conv2D object at 0x7fd8df625110>> could not be transformed and will be executed as-is. Please report this to the AutgoGraph team. When filing the bug, set the verbosity to 10 (on Linux, `export AUTOGRAPH_VERBOSITY=10`) and attach the full output. Cause: converting <bound method Conv.call of <tensorflow.python.layers.convolutional.Conv2D object at 0x7fd8df625110>>: AssertionError: Bad argument number for Name: 3, expecting 4\n",
      "WARNING: Entity <bound method Conv.call of <tensorflow.python.layers.convolutional.Conv2D object at 0x7fd8df625110>> could not be transformed and will be executed as-is. Please report this to the AutgoGraph team. When filing the bug, set the verbosity to 10 (on Linux, `export AUTOGRAPH_VERBOSITY=10`) and attach the full output. Cause: converting <bound method Conv.call of <tensorflow.python.layers.convolutional.Conv2D object at 0x7fd8df625110>>: AssertionError: Bad argument number for Name: 3, expecting 4\n",
      "WARNING:tensorflow:Entity <bound method Conv.call of <tensorflow.python.layers.convolutional.Conv2D object at 0x7fd8e07ee890>> could not be transformed and will be executed as-is. Please report this to the AutgoGraph team. When filing the bug, set the verbosity to 10 (on Linux, `export AUTOGRAPH_VERBOSITY=10`) and attach the full output. Cause: converting <bound method Conv.call of <tensorflow.python.layers.convolutional.Conv2D object at 0x7fd8e07ee890>>: AssertionError: Bad argument number for Name: 3, expecting 4\n",
      "WARNING: Entity <bound method Conv.call of <tensorflow.python.layers.convolutional.Conv2D object at 0x7fd8e07ee890>> could not be transformed and will be executed as-is. Please report this to the AutgoGraph team. When filing the bug, set the verbosity to 10 (on Linux, `export AUTOGRAPH_VERBOSITY=10`) and attach the full output. Cause: converting <bound method Conv.call of <tensorflow.python.layers.convolutional.Conv2D object at 0x7fd8e07ee890>>: AssertionError: Bad argument number for Name: 3, expecting 4\n",
      "WARNING:tensorflow:Entity <bound method Conv.call of <tensorflow.python.layers.convolutional.Conv2D object at 0x7fd8e07e8210>> could not be transformed and will be executed as-is. Please report this to the AutgoGraph team. When filing the bug, set the verbosity to 10 (on Linux, `export AUTOGRAPH_VERBOSITY=10`) and attach the full output. Cause: converting <bound method Conv.call of <tensorflow.python.layers.convolutional.Conv2D object at 0x7fd8e07e8210>>: AssertionError: Bad argument number for Name: 3, expecting 4\n",
      "WARNING: Entity <bound method Conv.call of <tensorflow.python.layers.convolutional.Conv2D object at 0x7fd8e07e8210>> could not be transformed and will be executed as-is. Please report this to the AutgoGraph team. When filing the bug, set the verbosity to 10 (on Linux, `export AUTOGRAPH_VERBOSITY=10`) and attach the full output. Cause: converting <bound method Conv.call of <tensorflow.python.layers.convolutional.Conv2D object at 0x7fd8e07e8210>>: AssertionError: Bad argument number for Name: 3, expecting 4\n",
      "WARNING:tensorflow:Entity <bound method Conv.call of <tensorflow.python.layers.convolutional.Conv2D object at 0x7fd8e07ee490>> could not be transformed and will be executed as-is. Please report this to the AutgoGraph team. When filing the bug, set the verbosity to 10 (on Linux, `export AUTOGRAPH_VERBOSITY=10`) and attach the full output. Cause: converting <bound method Conv.call of <tensorflow.python.layers.convolutional.Conv2D object at 0x7fd8e07ee490>>: AssertionError: Bad argument number for Name: 3, expecting 4\n",
      "WARNING: Entity <bound method Conv.call of <tensorflow.python.layers.convolutional.Conv2D object at 0x7fd8e07ee490>> could not be transformed and will be executed as-is. Please report this to the AutgoGraph team. When filing the bug, set the verbosity to 10 (on Linux, `export AUTOGRAPH_VERBOSITY=10`) and attach the full output. Cause: converting <bound method Conv.call of <tensorflow.python.layers.convolutional.Conv2D object at 0x7fd8e07ee490>>: AssertionError: Bad argument number for Name: 3, expecting 4\n",
      "WARNING:tensorflow:Entity <bound method Conv.call of <tensorflow.python.layers.convolutional.Conv2D object at 0x7fd8e07eea50>> could not be transformed and will be executed as-is. Please report this to the AutgoGraph team. When filing the bug, set the verbosity to 10 (on Linux, `export AUTOGRAPH_VERBOSITY=10`) and attach the full output. Cause: converting <bound method Conv.call of <tensorflow.python.layers.convolutional.Conv2D object at 0x7fd8e07eea50>>: AssertionError: Bad argument number for Name: 3, expecting 4\n"
     ]
    },
    {
     "name": "stdout",
     "output_type": "stream",
     "text": [
      "WARNING: Entity <bound method Conv.call of <tensorflow.python.layers.convolutional.Conv2D object at 0x7fd8e07eea50>> could not be transformed and will be executed as-is. Please report this to the AutgoGraph team. When filing the bug, set the verbosity to 10 (on Linux, `export AUTOGRAPH_VERBOSITY=10`) and attach the full output. Cause: converting <bound method Conv.call of <tensorflow.python.layers.convolutional.Conv2D object at 0x7fd8e07eea50>>: AssertionError: Bad argument number for Name: 3, expecting 4\n",
      "WARNING:tensorflow:Entity <bound method Conv.call of <tensorflow.python.layers.convolutional.Conv2D object at 0x7fd8e09c8b90>> could not be transformed and will be executed as-is. Please report this to the AutgoGraph team. When filing the bug, set the verbosity to 10 (on Linux, `export AUTOGRAPH_VERBOSITY=10`) and attach the full output. Cause: converting <bound method Conv.call of <tensorflow.python.layers.convolutional.Conv2D object at 0x7fd8e09c8b90>>: AssertionError: Bad argument number for Name: 3, expecting 4\n",
      "WARNING: Entity <bound method Conv.call of <tensorflow.python.layers.convolutional.Conv2D object at 0x7fd8e09c8b90>> could not be transformed and will be executed as-is. Please report this to the AutgoGraph team. When filing the bug, set the verbosity to 10 (on Linux, `export AUTOGRAPH_VERBOSITY=10`) and attach the full output. Cause: converting <bound method Conv.call of <tensorflow.python.layers.convolutional.Conv2D object at 0x7fd8e09c8b90>>: AssertionError: Bad argument number for Name: 3, expecting 4\n",
      "WARNING:tensorflow:Entity <bound method Conv.call of <tensorflow.python.layers.convolutional.Conv2D object at 0x7fd8e08c36d0>> could not be transformed and will be executed as-is. Please report this to the AutgoGraph team. When filing the bug, set the verbosity to 10 (on Linux, `export AUTOGRAPH_VERBOSITY=10`) and attach the full output. Cause: converting <bound method Conv.call of <tensorflow.python.layers.convolutional.Conv2D object at 0x7fd8e08c36d0>>: AssertionError: Bad argument number for Name: 3, expecting 4\n",
      "WARNING: Entity <bound method Conv.call of <tensorflow.python.layers.convolutional.Conv2D object at 0x7fd8e08c36d0>> could not be transformed and will be executed as-is. Please report this to the AutgoGraph team. When filing the bug, set the verbosity to 10 (on Linux, `export AUTOGRAPH_VERBOSITY=10`) and attach the full output. Cause: converting <bound method Conv.call of <tensorflow.python.layers.convolutional.Conv2D object at 0x7fd8e08c36d0>>: AssertionError: Bad argument number for Name: 3, expecting 4\n",
      "WARNING:tensorflow:From /Users/apple/opt/anaconda3/envs/tensorflow/lib/python3.7/site-packages/tensorflow/python/training/saver.py:1276: checkpoint_exists (from tensorflow.python.training.checkpoint_management) is deprecated and will be removed in a future version.\n",
      "Instructions for updating:\n",
      "Use standard file APIs to check for files with this prefix.\n",
      "INFO:tensorflow:Restoring parameters from ssd_300_vgg.ckpt\n"
     ]
    },
    {
     "ename": "DataLossError",
     "evalue": "Unable to open table file ./ssd_300_vgg.ckpt: Failed precondition: ssd_300_vgg.ckpt; Is a directory: perhaps your file is in a different file format and you need to use a different restore operator?\n\t [[node save/RestoreV2 (defined at <ipython-input-8-81e42f3897e3>:23) ]]\n\nOriginal stack trace for 'save/RestoreV2':\n  File \"/Users/apple/opt/anaconda3/envs/tensorflow/lib/python3.7/runpy.py\", line 193, in _run_module_as_main\n    \"__main__\", mod_spec)\n  File \"/Users/apple/opt/anaconda3/envs/tensorflow/lib/python3.7/runpy.py\", line 85, in _run_code\n    exec(code, run_globals)\n  File \"/Users/apple/opt/anaconda3/envs/tensorflow/lib/python3.7/site-packages/ipykernel_launcher.py\", line 16, in <module>\n    app.launch_new_instance()\n  File \"/Users/apple/opt/anaconda3/envs/tensorflow/lib/python3.7/site-packages/traitlets/config/application.py\", line 845, in launch_instance\n    app.start()\n  File \"/Users/apple/opt/anaconda3/envs/tensorflow/lib/python3.7/site-packages/ipykernel/kernelapp.py\", line 612, in start\n    self.io_loop.start()\n  File \"/Users/apple/opt/anaconda3/envs/tensorflow/lib/python3.7/site-packages/tornado/platform/asyncio.py\", line 199, in start\n    self.asyncio_loop.run_forever()\n  File \"/Users/apple/opt/anaconda3/envs/tensorflow/lib/python3.7/asyncio/base_events.py\", line 541, in run_forever\n    self._run_once()\n  File \"/Users/apple/opt/anaconda3/envs/tensorflow/lib/python3.7/asyncio/base_events.py\", line 1786, in _run_once\n    handle._run()\n  File \"/Users/apple/opt/anaconda3/envs/tensorflow/lib/python3.7/asyncio/events.py\", line 88, in _run\n    self._context.run(self._callback, *self._args)\n  File \"/Users/apple/opt/anaconda3/envs/tensorflow/lib/python3.7/site-packages/tornado/ioloop.py\", line 688, in <lambda>\n    lambda f: self._run_callback(functools.partial(callback, future))\n  File \"/Users/apple/opt/anaconda3/envs/tensorflow/lib/python3.7/site-packages/tornado/ioloop.py\", line 741, in _run_callback\n    ret = callback()\n  File \"/Users/apple/opt/anaconda3/envs/tensorflow/lib/python3.7/site-packages/tornado/gen.py\", line 814, in inner\n    self.ctx_run(self.run)\n  File \"/Users/apple/opt/anaconda3/envs/tensorflow/lib/python3.7/site-packages/tornado/gen.py\", line 775, in run\n    yielded = self.gen.send(value)\n  File \"/Users/apple/opt/anaconda3/envs/tensorflow/lib/python3.7/site-packages/ipykernel/kernelbase.py\", line 365, in process_one\n    yield gen.maybe_future(dispatch(*args))\n  File \"/Users/apple/opt/anaconda3/envs/tensorflow/lib/python3.7/site-packages/tornado/gen.py\", line 234, in wrapper\n    yielded = ctx_run(next, result)\n  File \"/Users/apple/opt/anaconda3/envs/tensorflow/lib/python3.7/site-packages/ipykernel/kernelbase.py\", line 268, in dispatch_shell\n    yield gen.maybe_future(handler(stream, idents, msg))\n  File \"/Users/apple/opt/anaconda3/envs/tensorflow/lib/python3.7/site-packages/tornado/gen.py\", line 234, in wrapper\n    yielded = ctx_run(next, result)\n  File \"/Users/apple/opt/anaconda3/envs/tensorflow/lib/python3.7/site-packages/ipykernel/kernelbase.py\", line 545, in execute_request\n    user_expressions, allow_stdin,\n  File \"/Users/apple/opt/anaconda3/envs/tensorflow/lib/python3.7/site-packages/tornado/gen.py\", line 234, in wrapper\n    yielded = ctx_run(next, result)\n  File \"/Users/apple/opt/anaconda3/envs/tensorflow/lib/python3.7/site-packages/ipykernel/ipkernel.py\", line 306, in do_execute\n    res = shell.run_cell(code, store_history=store_history, silent=silent)\n  File \"/Users/apple/opt/anaconda3/envs/tensorflow/lib/python3.7/site-packages/ipykernel/zmqshell.py\", line 536, in run_cell\n    return super(ZMQInteractiveShell, self).run_cell(*args, **kwargs)\n  File \"/Users/apple/opt/anaconda3/envs/tensorflow/lib/python3.7/site-packages/IPython/core/interactiveshell.py\", line 2895, in run_cell\n    raw_cell, store_history, silent, shell_futures)\n  File \"/Users/apple/opt/anaconda3/envs/tensorflow/lib/python3.7/site-packages/IPython/core/interactiveshell.py\", line 2940, in _run_cell\n    return runner(coro)\n  File \"/Users/apple/opt/anaconda3/envs/tensorflow/lib/python3.7/site-packages/IPython/core/async_helpers.py\", line 68, in _pseudo_sync_runner\n    coro.send(None)\n  File \"/Users/apple/opt/anaconda3/envs/tensorflow/lib/python3.7/site-packages/IPython/core/interactiveshell.py\", line 3166, in run_cell_async\n    interactivity=interactivity, compiler=compiler, result=result)\n  File \"/Users/apple/opt/anaconda3/envs/tensorflow/lib/python3.7/site-packages/IPython/core/interactiveshell.py\", line 3357, in run_ast_nodes\n    if (await self.run_code(code, result,  async_=asy)):\n  File \"/Users/apple/opt/anaconda3/envs/tensorflow/lib/python3.7/site-packages/IPython/core/interactiveshell.py\", line 3437, in run_code\n    exec(code_obj, self.user_global_ns, self.user_ns)\n  File \"<ipython-input-8-81e42f3897e3>\", line 23, in <module>\n    saver = tf.train.Saver()\n  File \"/Users/apple/opt/anaconda3/envs/tensorflow/lib/python3.7/site-packages/tensorflow/python/training/saver.py\", line 825, in __init__\n    self.build()\n  File \"/Users/apple/opt/anaconda3/envs/tensorflow/lib/python3.7/site-packages/tensorflow/python/training/saver.py\", line 837, in build\n    self._build(self._filename, build_save=True, build_restore=True)\n  File \"/Users/apple/opt/anaconda3/envs/tensorflow/lib/python3.7/site-packages/tensorflow/python/training/saver.py\", line 875, in _build\n    build_restore=build_restore)\n  File \"/Users/apple/opt/anaconda3/envs/tensorflow/lib/python3.7/site-packages/tensorflow/python/training/saver.py\", line 508, in _build_internal\n    restore_sequentially, reshape)\n  File \"/Users/apple/opt/anaconda3/envs/tensorflow/lib/python3.7/site-packages/tensorflow/python/training/saver.py\", line 328, in _AddRestoreOps\n    restore_sequentially)\n  File \"/Users/apple/opt/anaconda3/envs/tensorflow/lib/python3.7/site-packages/tensorflow/python/training/saver.py\", line 575, in bulk_restore\n    return io_ops.restore_v2(filename_tensor, names, slices, dtypes)\n  File \"/Users/apple/opt/anaconda3/envs/tensorflow/lib/python3.7/site-packages/tensorflow/python/ops/gen_io_ops.py\", line 1696, in restore_v2\n    name=name)\n  File \"/Users/apple/opt/anaconda3/envs/tensorflow/lib/python3.7/site-packages/tensorflow/python/framework/op_def_library.py\", line 788, in _apply_op_helper\n    op_def=op_def)\n  File \"/Users/apple/opt/anaconda3/envs/tensorflow/lib/python3.7/site-packages/tensorflow/python/util/deprecation.py\", line 507, in new_func\n    return func(*args, **kwargs)\n  File \"/Users/apple/opt/anaconda3/envs/tensorflow/lib/python3.7/site-packages/tensorflow/python/framework/ops.py\", line 3616, in create_op\n    op_def=op_def)\n  File \"/Users/apple/opt/anaconda3/envs/tensorflow/lib/python3.7/site-packages/tensorflow/python/framework/ops.py\", line 2005, in __init__\n    self._traceback = tf_stack.extract_stack()\n",
     "output_type": "error",
     "traceback": [
      "\u001b[0;31m---------------------------------------------------------------------------\u001b[0m",
      "\u001b[0;31mDataLossError\u001b[0m                             Traceback (most recent call last)",
      "\u001b[0;32m~/opt/anaconda3/envs/tensorflow/lib/python3.7/site-packages/tensorflow/python/client/session.py\u001b[0m in \u001b[0;36m_do_call\u001b[0;34m(self, fn, *args)\u001b[0m\n\u001b[1;32m   1355\u001b[0m     \u001b[0;32mtry\u001b[0m\u001b[0;34m:\u001b[0m\u001b[0;34m\u001b[0m\u001b[0;34m\u001b[0m\u001b[0m\n\u001b[0;32m-> 1356\u001b[0;31m       \u001b[0;32mreturn\u001b[0m \u001b[0mfn\u001b[0m\u001b[0;34m(\u001b[0m\u001b[0;34m*\u001b[0m\u001b[0margs\u001b[0m\u001b[0;34m)\u001b[0m\u001b[0;34m\u001b[0m\u001b[0;34m\u001b[0m\u001b[0m\n\u001b[0m\u001b[1;32m   1357\u001b[0m     \u001b[0;32mexcept\u001b[0m \u001b[0merrors\u001b[0m\u001b[0;34m.\u001b[0m\u001b[0mOpError\u001b[0m \u001b[0;32mas\u001b[0m \u001b[0me\u001b[0m\u001b[0;34m:\u001b[0m\u001b[0;34m\u001b[0m\u001b[0;34m\u001b[0m\u001b[0m\n",
      "\u001b[0;32m~/opt/anaconda3/envs/tensorflow/lib/python3.7/site-packages/tensorflow/python/client/session.py\u001b[0m in \u001b[0;36m_run_fn\u001b[0;34m(feed_dict, fetch_list, target_list, options, run_metadata)\u001b[0m\n\u001b[1;32m   1340\u001b[0m       return self._call_tf_sessionrun(\n\u001b[0;32m-> 1341\u001b[0;31m           options, feed_dict, fetch_list, target_list, run_metadata)\n\u001b[0m\u001b[1;32m   1342\u001b[0m \u001b[0;34m\u001b[0m\u001b[0m\n",
      "\u001b[0;32m~/opt/anaconda3/envs/tensorflow/lib/python3.7/site-packages/tensorflow/python/client/session.py\u001b[0m in \u001b[0;36m_call_tf_sessionrun\u001b[0;34m(self, options, feed_dict, fetch_list, target_list, run_metadata)\u001b[0m\n\u001b[1;32m   1428\u001b[0m         \u001b[0mself\u001b[0m\u001b[0;34m.\u001b[0m\u001b[0m_session\u001b[0m\u001b[0;34m,\u001b[0m \u001b[0moptions\u001b[0m\u001b[0;34m,\u001b[0m \u001b[0mfeed_dict\u001b[0m\u001b[0;34m,\u001b[0m \u001b[0mfetch_list\u001b[0m\u001b[0;34m,\u001b[0m \u001b[0mtarget_list\u001b[0m\u001b[0;34m,\u001b[0m\u001b[0;34m\u001b[0m\u001b[0;34m\u001b[0m\u001b[0m\n\u001b[0;32m-> 1429\u001b[0;31m         run_metadata)\n\u001b[0m\u001b[1;32m   1430\u001b[0m \u001b[0;34m\u001b[0m\u001b[0m\n",
      "\u001b[0;31mDataLossError\u001b[0m: Unable to open table file ./ssd_300_vgg.ckpt: Failed precondition: ssd_300_vgg.ckpt; Is a directory: perhaps your file is in a different file format and you need to use a different restore operator?\n\t [[{{node save/RestoreV2}}]]",
      "\nDuring handling of the above exception, another exception occurred:\n",
      "\u001b[0;31mDataLossError\u001b[0m                             Traceback (most recent call last)",
      "\u001b[0;32m<ipython-input-8-81e42f3897e3>\u001b[0m in \u001b[0;36m<module>\u001b[0;34m\u001b[0m\n\u001b[1;32m     22\u001b[0m \u001b[0misess\u001b[0m\u001b[0;34m.\u001b[0m\u001b[0mrun\u001b[0m\u001b[0;34m(\u001b[0m\u001b[0mtf\u001b[0m\u001b[0;34m.\u001b[0m\u001b[0mglobal_variables_initializer\u001b[0m\u001b[0;34m(\u001b[0m\u001b[0;34m)\u001b[0m\u001b[0;34m)\u001b[0m\u001b[0;34m\u001b[0m\u001b[0;34m\u001b[0m\u001b[0m\n\u001b[1;32m     23\u001b[0m \u001b[0msaver\u001b[0m \u001b[0;34m=\u001b[0m \u001b[0mtf\u001b[0m\u001b[0;34m.\u001b[0m\u001b[0mtrain\u001b[0m\u001b[0;34m.\u001b[0m\u001b[0mSaver\u001b[0m\u001b[0;34m(\u001b[0m\u001b[0;34m)\u001b[0m\u001b[0;34m\u001b[0m\u001b[0;34m\u001b[0m\u001b[0m\n\u001b[0;32m---> 24\u001b[0;31m \u001b[0msaver\u001b[0m\u001b[0;34m.\u001b[0m\u001b[0mrestore\u001b[0m\u001b[0;34m(\u001b[0m\u001b[0misess\u001b[0m\u001b[0;34m,\u001b[0m \u001b[0mckpt_filename\u001b[0m\u001b[0;34m)\u001b[0m\u001b[0;34m\u001b[0m\u001b[0;34m\u001b[0m\u001b[0m\n\u001b[0m\u001b[1;32m     25\u001b[0m \u001b[0;34m\u001b[0m\u001b[0m\n\u001b[1;32m     26\u001b[0m \u001b[0;31m# SSD default anchor boxes.\u001b[0m\u001b[0;34m\u001b[0m\u001b[0;34m\u001b[0m\u001b[0;34m\u001b[0m\u001b[0m\n",
      "\u001b[0;32m~/opt/anaconda3/envs/tensorflow/lib/python3.7/site-packages/tensorflow/python/training/saver.py\u001b[0m in \u001b[0;36mrestore\u001b[0;34m(self, sess, save_path)\u001b[0m\n\u001b[1;32m   1284\u001b[0m       \u001b[0;32melse\u001b[0m\u001b[0;34m:\u001b[0m\u001b[0;34m\u001b[0m\u001b[0;34m\u001b[0m\u001b[0m\n\u001b[1;32m   1285\u001b[0m         sess.run(self.saver_def.restore_op_name,\n\u001b[0;32m-> 1286\u001b[0;31m                  {self.saver_def.filename_tensor_name: save_path})\n\u001b[0m\u001b[1;32m   1287\u001b[0m     \u001b[0;32mexcept\u001b[0m \u001b[0merrors\u001b[0m\u001b[0;34m.\u001b[0m\u001b[0mNotFoundError\u001b[0m \u001b[0;32mas\u001b[0m \u001b[0merr\u001b[0m\u001b[0;34m:\u001b[0m\u001b[0;34m\u001b[0m\u001b[0;34m\u001b[0m\u001b[0m\n\u001b[1;32m   1288\u001b[0m       \u001b[0;31m# There are three common conditions that might cause this error:\u001b[0m\u001b[0;34m\u001b[0m\u001b[0;34m\u001b[0m\u001b[0;34m\u001b[0m\u001b[0m\n",
      "\u001b[0;32m~/opt/anaconda3/envs/tensorflow/lib/python3.7/site-packages/tensorflow/python/client/session.py\u001b[0m in \u001b[0;36mrun\u001b[0;34m(self, fetches, feed_dict, options, run_metadata)\u001b[0m\n\u001b[1;32m    948\u001b[0m     \u001b[0;32mtry\u001b[0m\u001b[0;34m:\u001b[0m\u001b[0;34m\u001b[0m\u001b[0;34m\u001b[0m\u001b[0m\n\u001b[1;32m    949\u001b[0m       result = self._run(None, fetches, feed_dict, options_ptr,\n\u001b[0;32m--> 950\u001b[0;31m                          run_metadata_ptr)\n\u001b[0m\u001b[1;32m    951\u001b[0m       \u001b[0;32mif\u001b[0m \u001b[0mrun_metadata\u001b[0m\u001b[0;34m:\u001b[0m\u001b[0;34m\u001b[0m\u001b[0;34m\u001b[0m\u001b[0m\n\u001b[1;32m    952\u001b[0m         \u001b[0mproto_data\u001b[0m \u001b[0;34m=\u001b[0m \u001b[0mtf_session\u001b[0m\u001b[0;34m.\u001b[0m\u001b[0mTF_GetBuffer\u001b[0m\u001b[0;34m(\u001b[0m\u001b[0mrun_metadata_ptr\u001b[0m\u001b[0;34m)\u001b[0m\u001b[0;34m\u001b[0m\u001b[0;34m\u001b[0m\u001b[0m\n",
      "\u001b[0;32m~/opt/anaconda3/envs/tensorflow/lib/python3.7/site-packages/tensorflow/python/client/session.py\u001b[0m in \u001b[0;36m_run\u001b[0;34m(self, handle, fetches, feed_dict, options, run_metadata)\u001b[0m\n\u001b[1;32m   1171\u001b[0m     \u001b[0;32mif\u001b[0m \u001b[0mfinal_fetches\u001b[0m \u001b[0;32mor\u001b[0m \u001b[0mfinal_targets\u001b[0m \u001b[0;32mor\u001b[0m \u001b[0;34m(\u001b[0m\u001b[0mhandle\u001b[0m \u001b[0;32mand\u001b[0m \u001b[0mfeed_dict_tensor\u001b[0m\u001b[0;34m)\u001b[0m\u001b[0;34m:\u001b[0m\u001b[0;34m\u001b[0m\u001b[0;34m\u001b[0m\u001b[0m\n\u001b[1;32m   1172\u001b[0m       results = self._do_run(handle, final_targets, final_fetches,\n\u001b[0;32m-> 1173\u001b[0;31m                              feed_dict_tensor, options, run_metadata)\n\u001b[0m\u001b[1;32m   1174\u001b[0m     \u001b[0;32melse\u001b[0m\u001b[0;34m:\u001b[0m\u001b[0;34m\u001b[0m\u001b[0;34m\u001b[0m\u001b[0m\n\u001b[1;32m   1175\u001b[0m       \u001b[0mresults\u001b[0m \u001b[0;34m=\u001b[0m \u001b[0;34m[\u001b[0m\u001b[0;34m]\u001b[0m\u001b[0;34m\u001b[0m\u001b[0;34m\u001b[0m\u001b[0m\n",
      "\u001b[0;32m~/opt/anaconda3/envs/tensorflow/lib/python3.7/site-packages/tensorflow/python/client/session.py\u001b[0m in \u001b[0;36m_do_run\u001b[0;34m(self, handle, target_list, fetch_list, feed_dict, options, run_metadata)\u001b[0m\n\u001b[1;32m   1348\u001b[0m     \u001b[0;32mif\u001b[0m \u001b[0mhandle\u001b[0m \u001b[0;32mis\u001b[0m \u001b[0;32mNone\u001b[0m\u001b[0;34m:\u001b[0m\u001b[0;34m\u001b[0m\u001b[0;34m\u001b[0m\u001b[0m\n\u001b[1;32m   1349\u001b[0m       return self._do_call(_run_fn, feeds, fetches, targets, options,\n\u001b[0;32m-> 1350\u001b[0;31m                            run_metadata)\n\u001b[0m\u001b[1;32m   1351\u001b[0m     \u001b[0;32melse\u001b[0m\u001b[0;34m:\u001b[0m\u001b[0;34m\u001b[0m\u001b[0;34m\u001b[0m\u001b[0m\n\u001b[1;32m   1352\u001b[0m       \u001b[0;32mreturn\u001b[0m \u001b[0mself\u001b[0m\u001b[0;34m.\u001b[0m\u001b[0m_do_call\u001b[0m\u001b[0;34m(\u001b[0m\u001b[0m_prun_fn\u001b[0m\u001b[0;34m,\u001b[0m \u001b[0mhandle\u001b[0m\u001b[0;34m,\u001b[0m \u001b[0mfeeds\u001b[0m\u001b[0;34m,\u001b[0m \u001b[0mfetches\u001b[0m\u001b[0;34m)\u001b[0m\u001b[0;34m\u001b[0m\u001b[0;34m\u001b[0m\u001b[0m\n",
      "\u001b[0;32m~/opt/anaconda3/envs/tensorflow/lib/python3.7/site-packages/tensorflow/python/client/session.py\u001b[0m in \u001b[0;36m_do_call\u001b[0;34m(self, fn, *args)\u001b[0m\n\u001b[1;32m   1368\u001b[0m           \u001b[0;32mpass\u001b[0m\u001b[0;34m\u001b[0m\u001b[0;34m\u001b[0m\u001b[0m\n\u001b[1;32m   1369\u001b[0m       \u001b[0mmessage\u001b[0m \u001b[0;34m=\u001b[0m \u001b[0merror_interpolation\u001b[0m\u001b[0;34m.\u001b[0m\u001b[0minterpolate\u001b[0m\u001b[0;34m(\u001b[0m\u001b[0mmessage\u001b[0m\u001b[0;34m,\u001b[0m \u001b[0mself\u001b[0m\u001b[0;34m.\u001b[0m\u001b[0m_graph\u001b[0m\u001b[0;34m)\u001b[0m\u001b[0;34m\u001b[0m\u001b[0;34m\u001b[0m\u001b[0m\n\u001b[0;32m-> 1370\u001b[0;31m       \u001b[0;32mraise\u001b[0m \u001b[0mtype\u001b[0m\u001b[0;34m(\u001b[0m\u001b[0me\u001b[0m\u001b[0;34m)\u001b[0m\u001b[0;34m(\u001b[0m\u001b[0mnode_def\u001b[0m\u001b[0;34m,\u001b[0m \u001b[0mop\u001b[0m\u001b[0;34m,\u001b[0m \u001b[0mmessage\u001b[0m\u001b[0;34m)\u001b[0m\u001b[0;34m\u001b[0m\u001b[0;34m\u001b[0m\u001b[0m\n\u001b[0m\u001b[1;32m   1371\u001b[0m \u001b[0;34m\u001b[0m\u001b[0m\n\u001b[1;32m   1372\u001b[0m   \u001b[0;32mdef\u001b[0m \u001b[0m_extend_graph\u001b[0m\u001b[0;34m(\u001b[0m\u001b[0mself\u001b[0m\u001b[0;34m)\u001b[0m\u001b[0;34m:\u001b[0m\u001b[0;34m\u001b[0m\u001b[0;34m\u001b[0m\u001b[0m\n",
      "\u001b[0;31mDataLossError\u001b[0m: Unable to open table file ./ssd_300_vgg.ckpt: Failed precondition: ssd_300_vgg.ckpt; Is a directory: perhaps your file is in a different file format and you need to use a different restore operator?\n\t [[node save/RestoreV2 (defined at <ipython-input-8-81e42f3897e3>:23) ]]\n\nOriginal stack trace for 'save/RestoreV2':\n  File \"/Users/apple/opt/anaconda3/envs/tensorflow/lib/python3.7/runpy.py\", line 193, in _run_module_as_main\n    \"__main__\", mod_spec)\n  File \"/Users/apple/opt/anaconda3/envs/tensorflow/lib/python3.7/runpy.py\", line 85, in _run_code\n    exec(code, run_globals)\n  File \"/Users/apple/opt/anaconda3/envs/tensorflow/lib/python3.7/site-packages/ipykernel_launcher.py\", line 16, in <module>\n    app.launch_new_instance()\n  File \"/Users/apple/opt/anaconda3/envs/tensorflow/lib/python3.7/site-packages/traitlets/config/application.py\", line 845, in launch_instance\n    app.start()\n  File \"/Users/apple/opt/anaconda3/envs/tensorflow/lib/python3.7/site-packages/ipykernel/kernelapp.py\", line 612, in start\n    self.io_loop.start()\n  File \"/Users/apple/opt/anaconda3/envs/tensorflow/lib/python3.7/site-packages/tornado/platform/asyncio.py\", line 199, in start\n    self.asyncio_loop.run_forever()\n  File \"/Users/apple/opt/anaconda3/envs/tensorflow/lib/python3.7/asyncio/base_events.py\", line 541, in run_forever\n    self._run_once()\n  File \"/Users/apple/opt/anaconda3/envs/tensorflow/lib/python3.7/asyncio/base_events.py\", line 1786, in _run_once\n    handle._run()\n  File \"/Users/apple/opt/anaconda3/envs/tensorflow/lib/python3.7/asyncio/events.py\", line 88, in _run\n    self._context.run(self._callback, *self._args)\n  File \"/Users/apple/opt/anaconda3/envs/tensorflow/lib/python3.7/site-packages/tornado/ioloop.py\", line 688, in <lambda>\n    lambda f: self._run_callback(functools.partial(callback, future))\n  File \"/Users/apple/opt/anaconda3/envs/tensorflow/lib/python3.7/site-packages/tornado/ioloop.py\", line 741, in _run_callback\n    ret = callback()\n  File \"/Users/apple/opt/anaconda3/envs/tensorflow/lib/python3.7/site-packages/tornado/gen.py\", line 814, in inner\n    self.ctx_run(self.run)\n  File \"/Users/apple/opt/anaconda3/envs/tensorflow/lib/python3.7/site-packages/tornado/gen.py\", line 775, in run\n    yielded = self.gen.send(value)\n  File \"/Users/apple/opt/anaconda3/envs/tensorflow/lib/python3.7/site-packages/ipykernel/kernelbase.py\", line 365, in process_one\n    yield gen.maybe_future(dispatch(*args))\n  File \"/Users/apple/opt/anaconda3/envs/tensorflow/lib/python3.7/site-packages/tornado/gen.py\", line 234, in wrapper\n    yielded = ctx_run(next, result)\n  File \"/Users/apple/opt/anaconda3/envs/tensorflow/lib/python3.7/site-packages/ipykernel/kernelbase.py\", line 268, in dispatch_shell\n    yield gen.maybe_future(handler(stream, idents, msg))\n  File \"/Users/apple/opt/anaconda3/envs/tensorflow/lib/python3.7/site-packages/tornado/gen.py\", line 234, in wrapper\n    yielded = ctx_run(next, result)\n  File \"/Users/apple/opt/anaconda3/envs/tensorflow/lib/python3.7/site-packages/ipykernel/kernelbase.py\", line 545, in execute_request\n    user_expressions, allow_stdin,\n  File \"/Users/apple/opt/anaconda3/envs/tensorflow/lib/python3.7/site-packages/tornado/gen.py\", line 234, in wrapper\n    yielded = ctx_run(next, result)\n  File \"/Users/apple/opt/anaconda3/envs/tensorflow/lib/python3.7/site-packages/ipykernel/ipkernel.py\", line 306, in do_execute\n    res = shell.run_cell(code, store_history=store_history, silent=silent)\n  File \"/Users/apple/opt/anaconda3/envs/tensorflow/lib/python3.7/site-packages/ipykernel/zmqshell.py\", line 536, in run_cell\n    return super(ZMQInteractiveShell, self).run_cell(*args, **kwargs)\n  File \"/Users/apple/opt/anaconda3/envs/tensorflow/lib/python3.7/site-packages/IPython/core/interactiveshell.py\", line 2895, in run_cell\n    raw_cell, store_history, silent, shell_futures)\n  File \"/Users/apple/opt/anaconda3/envs/tensorflow/lib/python3.7/site-packages/IPython/core/interactiveshell.py\", line 2940, in _run_cell\n    return runner(coro)\n  File \"/Users/apple/opt/anaconda3/envs/tensorflow/lib/python3.7/site-packages/IPython/core/async_helpers.py\", line 68, in _pseudo_sync_runner\n    coro.send(None)\n  File \"/Users/apple/opt/anaconda3/envs/tensorflow/lib/python3.7/site-packages/IPython/core/interactiveshell.py\", line 3166, in run_cell_async\n    interactivity=interactivity, compiler=compiler, result=result)\n  File \"/Users/apple/opt/anaconda3/envs/tensorflow/lib/python3.7/site-packages/IPython/core/interactiveshell.py\", line 3357, in run_ast_nodes\n    if (await self.run_code(code, result,  async_=asy)):\n  File \"/Users/apple/opt/anaconda3/envs/tensorflow/lib/python3.7/site-packages/IPython/core/interactiveshell.py\", line 3437, in run_code\n    exec(code_obj, self.user_global_ns, self.user_ns)\n  File \"<ipython-input-8-81e42f3897e3>\", line 23, in <module>\n    saver = tf.train.Saver()\n  File \"/Users/apple/opt/anaconda3/envs/tensorflow/lib/python3.7/site-packages/tensorflow/python/training/saver.py\", line 825, in __init__\n    self.build()\n  File \"/Users/apple/opt/anaconda3/envs/tensorflow/lib/python3.7/site-packages/tensorflow/python/training/saver.py\", line 837, in build\n    self._build(self._filename, build_save=True, build_restore=True)\n  File \"/Users/apple/opt/anaconda3/envs/tensorflow/lib/python3.7/site-packages/tensorflow/python/training/saver.py\", line 875, in _build\n    build_restore=build_restore)\n  File \"/Users/apple/opt/anaconda3/envs/tensorflow/lib/python3.7/site-packages/tensorflow/python/training/saver.py\", line 508, in _build_internal\n    restore_sequentially, reshape)\n  File \"/Users/apple/opt/anaconda3/envs/tensorflow/lib/python3.7/site-packages/tensorflow/python/training/saver.py\", line 328, in _AddRestoreOps\n    restore_sequentially)\n  File \"/Users/apple/opt/anaconda3/envs/tensorflow/lib/python3.7/site-packages/tensorflow/python/training/saver.py\", line 575, in bulk_restore\n    return io_ops.restore_v2(filename_tensor, names, slices, dtypes)\n  File \"/Users/apple/opt/anaconda3/envs/tensorflow/lib/python3.7/site-packages/tensorflow/python/ops/gen_io_ops.py\", line 1696, in restore_v2\n    name=name)\n  File \"/Users/apple/opt/anaconda3/envs/tensorflow/lib/python3.7/site-packages/tensorflow/python/framework/op_def_library.py\", line 788, in _apply_op_helper\n    op_def=op_def)\n  File \"/Users/apple/opt/anaconda3/envs/tensorflow/lib/python3.7/site-packages/tensorflow/python/util/deprecation.py\", line 507, in new_func\n    return func(*args, **kwargs)\n  File \"/Users/apple/opt/anaconda3/envs/tensorflow/lib/python3.7/site-packages/tensorflow/python/framework/ops.py\", line 3616, in create_op\n    op_def=op_def)\n  File \"/Users/apple/opt/anaconda3/envs/tensorflow/lib/python3.7/site-packages/tensorflow/python/framework/ops.py\", line 2005, in __init__\n    self._traceback = tf_stack.extract_stack()\n"
     ]
    }
   ],
   "source": [
    "#%tensorflow_version 1.x\n",
    "import warnings\n",
    "warnings.filterwarnings('ignore')\n",
    "# Input placeholder.\n",
    "net_shape = (300, 300)\n",
    "data_format = 'NHWC'\n",
    "img_input = tf.placeholder(tf.uint8, shape=(None, None, 3))\n",
    "# Evaluation pre-processing: resize to SSD net shape.\n",
    "image_pre, labels_pre, bboxes_pre, bbox_img = ssd_vgg_preprocessing.preprocess_for_eval(\n",
    "    img_input, None, None, net_shape, data_format, resize=ssd_vgg_preprocessing.Resize.WARP_RESIZE)\n",
    "image_4d = tf.expand_dims(image_pre, 0)\n",
    "\n",
    "# Define the SSD model.\n",
    "reuse = True if 'ssd_net' in locals() else None\n",
    "ssd_net = ssd_vgg_300.SSDNet()\n",
    "with slim.arg_scope(ssd_net.arg_scope(data_format=data_format)):\n",
    "    predictions, localisations, _, _ = ssd_net.net(image_4d, is_training=False, reuse=reuse)\n",
    "\n",
    "# Restore SSD model.\n",
    "ckpt_filename = '../checkpoints/ssd_300_vgg.ckpt'\n",
    "# ckpt_filename = '../checkpoints/VGG_VOC0712_SSD_300x300_ft_iter_120000.ckpt'\n",
    "isess.run(tf.global_variables_initializer())\n",
    "saver = tf.train.Saver()\n",
    "saver.restore(isess, ckpt_filename)\n",
    "\n",
    "# SSD default anchor boxes.\n",
    "ssd_anchors = ssd_net.anchors(net_shape)"
   ]
  },
  {
   "cell_type": "markdown",
   "metadata": {},
   "source": [
    "## Post-processing pipeline\n",
    "\n",
    "The SSD outputs need to be post-processed to provide proper detections. Namely, we follow these common steps:\n",
    "\n",
    "* Select boxes above a classification threshold;\n",
    "* Clip boxes to the image shape;\n",
    "* Apply the Non-Maximum-Selection algorithm: fuse together boxes whose Jaccard score > threshold;\n",
    "* If necessary, resize bounding boxes to original image shape."
   ]
  },
  {
   "cell_type": "code",
   "execution_count": 9,
   "metadata": {
    "scrolled": true
   },
   "outputs": [],
   "source": [
    "# Main image processing routine.\n",
    "def process_image(img, select_threshold=0.5, nms_threshold=.45, net_shape=(300, 300)):\n",
    "    # Run SSD network.\n",
    "    rimg, rpredictions, rlocalisations, rbbox_img = isess.run([image_4d, predictions, localisations, bbox_img],\n",
    "                                                              feed_dict={img_input: img})\n",
    "    \n",
    "    # Get classes and bboxes from the net outputs.\n",
    "    rclasses, rscores, rbboxes = np_methods.ssd_bboxes_select(\n",
    "            rpredictions, rlocalisations, ssd_anchors,\n",
    "            select_threshold=select_threshold, img_shape=net_shape, num_classes=21, decode=True)\n",
    "    \n",
    "    rbboxes = np_methods.bboxes_clip(rbbox_img, rbboxes)\n",
    "    rclasses, rscores, rbboxes = np_methods.bboxes_sort(rclasses, rscores, rbboxes, top_k=400)\n",
    "    rclasses, rscores, rbboxes = np_methods.bboxes_nms(rclasses, rscores, rbboxes, nms_threshold=nms_threshold)\n",
    "    # Resize bboxes to original image shape. Note: useless for Resize.WARP!\n",
    "    rbboxes = np_methods.bboxes_resize(rbbox_img, rbboxes)\n",
    "    return rclasses, rscores, rbboxes"
   ]
  },
  {
   "cell_type": "code",
   "execution_count": 10,
   "metadata": {
    "scrolled": false
   },
   "outputs": [
    {
     "ename": "NameError",
     "evalue": "name 'ssd_anchors' is not defined",
     "output_type": "error",
     "traceback": [
      "\u001b[0;31m---------------------------------------------------------------------------\u001b[0m",
      "\u001b[0;31mNameError\u001b[0m                                 Traceback (most recent call last)",
      "\u001b[0;32m<ipython-input-10-64dd4ec290e9>\u001b[0m in \u001b[0;36m<module>\u001b[0;34m\u001b[0m\n\u001b[1;32m      4\u001b[0m \u001b[0;34m\u001b[0m\u001b[0m\n\u001b[1;32m      5\u001b[0m \u001b[0mimg\u001b[0m \u001b[0;34m=\u001b[0m \u001b[0mmpimg\u001b[0m\u001b[0;34m.\u001b[0m\u001b[0mimread\u001b[0m\u001b[0;34m(\u001b[0m\u001b[0mpath\u001b[0m \u001b[0;34m+\u001b[0m \u001b[0mimage_names\u001b[0m\u001b[0;34m[\u001b[0m\u001b[0;34m-\u001b[0m\u001b[0;36m5\u001b[0m\u001b[0;34m]\u001b[0m\u001b[0;34m)\u001b[0m\u001b[0;34m\u001b[0m\u001b[0;34m\u001b[0m\u001b[0m\n\u001b[0;32m----> 6\u001b[0;31m \u001b[0mrclasses\u001b[0m\u001b[0;34m,\u001b[0m \u001b[0mrscores\u001b[0m\u001b[0;34m,\u001b[0m \u001b[0mrbboxes\u001b[0m \u001b[0;34m=\u001b[0m  \u001b[0mprocess_image\u001b[0m\u001b[0;34m(\u001b[0m\u001b[0mimg\u001b[0m\u001b[0;34m)\u001b[0m\u001b[0;34m\u001b[0m\u001b[0;34m\u001b[0m\u001b[0m\n\u001b[0m\u001b[1;32m      7\u001b[0m \u001b[0;34m\u001b[0m\u001b[0m\n\u001b[1;32m      8\u001b[0m \u001b[0;31m# visualization.bboxes_draw_on_img(img, rclasses, rscores, rbboxes, visualization.colors_plasma)\u001b[0m\u001b[0;34m\u001b[0m\u001b[0;34m\u001b[0m\u001b[0;34m\u001b[0m\u001b[0m\n",
      "\u001b[0;32m<ipython-input-9-633d764f0cde>\u001b[0m in \u001b[0;36mprocess_image\u001b[0;34m(img, select_threshold, nms_threshold, net_shape)\u001b[0m\n\u001b[1;32m      7\u001b[0m     \u001b[0;31m# Get classes and bboxes from the net outputs.\u001b[0m\u001b[0;34m\u001b[0m\u001b[0;34m\u001b[0m\u001b[0;34m\u001b[0m\u001b[0m\n\u001b[1;32m      8\u001b[0m     rclasses, rscores, rbboxes = np_methods.ssd_bboxes_select(\n\u001b[0;32m----> 9\u001b[0;31m             \u001b[0mrpredictions\u001b[0m\u001b[0;34m,\u001b[0m \u001b[0mrlocalisations\u001b[0m\u001b[0;34m,\u001b[0m \u001b[0mssd_anchors\u001b[0m\u001b[0;34m,\u001b[0m\u001b[0;34m\u001b[0m\u001b[0;34m\u001b[0m\u001b[0m\n\u001b[0m\u001b[1;32m     10\u001b[0m             select_threshold=select_threshold, img_shape=net_shape, num_classes=21, decode=True)\n\u001b[1;32m     11\u001b[0m \u001b[0;34m\u001b[0m\u001b[0m\n",
      "\u001b[0;31mNameError\u001b[0m: name 'ssd_anchors' is not defined"
     ]
    }
   ],
   "source": [
    "# Test on some demo image and visualize output.\n",
    "path = '../demo/'\n",
    "image_names = sorted(os.listdir(path))\n",
    "\n",
    "img = mpimg.imread(path + image_names[-5])\n",
    "rclasses, rscores, rbboxes =  process_image(img)\n",
    "\n",
    "# visualization.bboxes_draw_on_img(img, rclasses, rscores, rbboxes, visualization.colors_plasma)\n",
    "visualization.plt_bboxes(img, rclasses, rscores, rbboxes)"
   ]
  },
  {
   "cell_type": "code",
   "execution_count": null,
   "metadata": {},
   "outputs": [],
   "source": []
  },
  {
   "cell_type": "code",
   "execution_count": null,
   "metadata": {},
   "outputs": [],
   "source": []
  },
  {
   "cell_type": "code",
   "execution_count": null,
   "metadata": {
    "collapsed": true
   },
   "outputs": [],
   "source": []
  },
  {
   "cell_type": "code",
   "execution_count": null,
   "metadata": {
    "collapsed": true
   },
   "outputs": [],
   "source": []
  }
 ],
 "metadata": {
  "kernelspec": {
   "display_name": "Python 3",
   "language": "python",
   "name": "python3"
  },
  "language_info": {
   "codemirror_mode": {
    "name": "ipython",
    "version": 3
   },
   "file_extension": ".py",
   "mimetype": "text/x-python",
   "name": "python",
   "nbconvert_exporter": "python",
   "pygments_lexer": "ipython3",
   "version": "3.7.10"
  }
 },
 "nbformat": 4,
 "nbformat_minor": 2
}
